Workbook

Sheet wallet_records
A1: account | B1: category | C1: currency | D1: amount | E1: ref_currency_amount | F1: type | G1: payment_type | H1: note | I1: date | J1: transfer | K1: payee | L1: labels | M1: día | N1: mes | O1: año
A2: Bancolombia | B2: Empleados | C2: COP | D2: 1051000 | E2: 1051000 | F2: Gasto | G2: Transferencia bancaria | H2: MLUJ | I2: 46071.5 | J2: FALSE | K2: Martha Lucia Uribe Jaramillo | L2: Martha Lucía Uribe Jaramillo | M2: 18 | N2: 2 | O2: 2026 | R2: =IF(wallet_records[[#This Row],[type]]="Gasto",wallet_records[[#This Row],[amount]]*(-1),wallet_records[[#This Row],[amount]]) -> -1051000
A3: Bancolombia | B3: Empleados | C3: COP | D3: 1051000 | E3: 1051000 | F3: Gasto | G3: Transferencia bancaria | H3: MLUJ | I3: 46057.5 | J3: FALSE | K3: Martha Lucia Uribe Jaramillo | L3: Martha Lucía Uribe Jaramillo | M3: 4 | N3: 2 | O3: 2026 | R3: =IF(wallet_records[[#This Row],[type]]="Gasto",wallet_records[[#This Row],[amount]]*(-1),wallet_records[[#This Row],[amount]]) -> -1051000
A4: Bancolombia | B4: Empleados | C4: COP | D4: 218900 | E4: 218900 | F4: Gasto | G4: Transferencia bancaria | H4: Seguridad Social | I4: 46054.5 | J4: FALSE | K4: Martha Lucia Uribe Jaramillo | L4: Martha Lucía Uribe Jaramillo | M4: 1 | N4: 2 | O4: 2026 | R4: =IF(wallet_records[[#This Row],[type]]="Gasto",wallet_records[[#This Row],[amount]]*(-1),wallet_records[[#This Row],[amount]]) -> -218900
A5: Bancolombia | B5: Empleados | C5: COP | D5: 575300 | E5: 575300 | F5: Gasto | G5: Transferencia bancaria | H5: Seguridad Social | I5: 46054.5 | J5: FALSE | K5: Eliecer Restrepo Restrepo | L5: Eliecer Restrepo Restrepo | M5: 1 | N5: 2 | O5: 2026 | R5: =IF(wallet_records[[#This Row],[type]]="Gasto",wallet_records[[#This Row],[amount]]*(-1),wallet_records[[#This Row],[amount]]) -> -575300
A6: Bancolombia | B6: Empleados | C6: COP | D6: 1051000 | E6: 1051000 | F6: Gasto | G6: Transferencia bancaria | H6: MLUJ | I6: 46042.5 | J6: FALSE | K6: Martha Lucia Uribe Jaramillo | L6: Martha Lucía Uribe Jaramillo | M6: 20 | N6: 1 | O6: 2026 | R6: =IF(wallet_records[[#This Row],[type]]="Gasto",wallet_records[[#This Row],[amount]]*(-1),wallet_records[[#This Row],[amount]]) -> -1051000
A7: Bancolombia | B7: Empleados | C7: COP | D7: 178000 | E7: 178000 | F7: Gasto | G7: Transferencia bancaria | H7: Seguridad Social | I7: 46027.501 | J7: FALSE | K7: Martha Lucia Uribe Jaramillo | L7: Martha Lucía Uribe Jaramillo | M7: 5 | N7: 1 | O7: 2026 | R7: =IF(wallet_records[[#This Row],[type]]="Gasto",wallet_records[[#This Row],[amount]]*(-1),wallet_records[[#This Row],[amount]]) -> -178000
A8: Efectivo | B8: Empleados | C8: COP | D8: 575300 | E8: 575300 | F8: Gasto | G8: Transferencia bancaria | H8: Seguridad Social | I8: 46027.5 | J8: FALSE | K8: Eliecer Restrepo Restrepo | L8: Eliecer Restrepo Restrepo | M8: 5 | N8: 1 | O8: 2026 | R8: =IF(wallet_records[[#This Row],[type]]="Gasto",wallet_records[[#This Row],[amount]]*(-1),wallet_records[[#This Row],[amount]]) -> -575300
A9: Bancolombia | B9: Empleados | C9: COP | D9: 1053000 | E9: 1053000 | F9: Gasto | G9: Transferencia bancaria | H9: MLUJ | I9: 46027.5 | J9: FALSE | K9: Martha Lucia Uribe Jaramillo | L9: Martha Lucía Uribe Jaramillo | M9: 5 | N9: 1 | O9: 2026 | R9: =IF(wallet_records[[#This Row],[type]]="Gasto",wallet_records[[#This Row],[amount]]*(-1),wallet_records[[#This Row],[amount]]) -> -1053000
A10: Bancolombia | B10: Impuestos - IVA, renta, otros | C10: COP | D10: 4431940 | E10: 4431940 | F10: Gasto | G10: Transferencia bancaria | H10: Impuesto Predial | I10: 46054.5 | J10: FALSE | K10: Municipio de Medellín | L10: Belén | M10: 1 | N10: 2 | O10: 2026 | R10: =IF(wallet_records[[#This Row],[type]]="Gasto",wallet_records[[#This Row],[amount]]*(-1),wallet_records[[#This Row],[amount]]) -> -4431940
A11: Bancolombia | B11: Impuestos - IVA, renta, otros | C11: COP | D11: 2461875 | E11: 2461875 | F11: Gasto | G11: Transferencia bancaria | H11: Impuesto Predial | I11: 46054.5 | J11: FALSE | K11: Municipio de Medellín | L11: Yari | M11: 1 | N11: 2 | O11: 2026 | R11: =IF(wallet_records[[#This Row],[type]]="Gasto",wallet_records[[#This Row],[amount]]*(-1),wallet_records[[#This Row],[amount]]) -> -2461875
A12: Bancolombia | B12: Impuestos - IVA, renta, otros | C12: COP | D12: 1320857 | E12: 1320857 | F12: Gasto | G12: Transferencia bancaria | H12: Impuesto Predial | I12: 46054.5 | J12: FALSE | K12: Municipio de Medellín | L12: Rivera del Valle | M12: 1 | N12: 2 | O12: 2026 | R12: =IF(wallet_records[[#This Row],[type]]="Gasto",wallet_records[[#This Row],[amount]]*(-1),wallet_records[[#This Row],[amount]]) -> -1320857
A13: Bancolombia | B13: Impuestos - IVA, renta, otros | C13: COP | D13: 1823377 | E13: 1823377 | F13: Gasto | G13: Transferencia bancaria | H13: Impuesto Predial | I13: 46054.5 | J13: FALSE | K13: Municipio de Medellín | L13: Ocarinas | M13: 1 | N13: 2 | O13: 2026 | R13: =IF(wallet_records[[#This Row],[type]]="Gasto",wallet_records[[#This Row],[amount]]*(-1),wallet_records[[#This Row],[amount]]) -> -1823377
A14: Bancolombia | B14: Impuestos - IVA, renta, otros | C14: COP | D14: 359256 | E14: 359256 | F14: Gasto | G14: Transferencia bancaria | H14: Impuesto Predial | I14: 46054.5 | J14: FALSE | K14: Municipio de Medellín | L14: Pedregal | M14: 1 | N14: 2 | O14: 2026 | R14: =IF(wallet_records[[#This Row],[type]]="Gasto",wallet_records[[#This Row],[amount]]*(-1),wallet_records[[#This Row],[amount]]) -> -359256
A15: Bancolombia | B15: Impuestos - IVA, renta, otros | C15: COP | D15: 227100 | E15: 227100 | F15: Gasto | G15: Transferencia bancaria | H15: Impuestos Mazda | I15: 46054.5 | J15: FALSE | L15: Mazda | M15: 1 | N15: 2 | O15: 2026 | R15: =IF(wallet_records[[#This Row],[type]]="Gasto",wallet_records[[#This Row],[amount]]*(-1),wallet_records[[#This Row],[amount]]) -> -227100
A16: Fidu Impuestos | B16: Impuestos - IVA, renta, otros | C16: COP | D16: 8610.12 | E16: 8610.12 | F16: Gasto | G16: Transferencia bancaria | H16: Retención en la Fuente | I16: 46052.397 | J16: FALSE | M16: 30 | N16: 1 | O16: 2026 | R16: =IF(wallet_records[[#This Row],[type]]="Gasto",wallet_records[[#This Row],[amount]]*(-1),wallet_records[[#This Row],[amount]]) -> -8610.12
A17: Bancolombia | B17: Impuestos - IVA, renta, otros | C17: COP | D17: 42900 | E17: 42900 | F17: Gasto | G17: Transferencia bancaria | H17: Semaforización Mazda | I17: 46042.5 | J17: FALSE | L17: Mazda | M17: 20 | N17: 1 | O17: 2026 | R17: =IF(wallet_records[[#This Row],[type]]="Gasto",wallet_records[[#This Row],[amount]]*(-1),wallet_records[[#This Row],[amount]]) -> -42900
A18: Bancolombia | B18: Intereses, cargos, seguros | C18: COP | D18: 2194118 | E18: 2194118 | F18: Gasto | G18: Transferencia bancaria | H18: Seguro taxi | I18: 46042.5 | J18: FALSE | L18: Taxi | M18: 20 | N18: 1 | O18: 2026 | R18: =IF(wallet_records[[#This Row],[type]]="Gasto",wallet_records[[#This Row],[amount]]*(-1),wallet_records[[#This Row],[amount]]) -> -2194118
A19: Bancolombia | B19: Intereses, cargos, seguros | C19: COP | D19: 677400 | E19: 677400 | F19: Gasto | G19: Transferencia bancaria | H19: SOAT Mazda | I19: 46027.464 | J19: FALSE | K19: Mazda | L19: Mazda | M19: 5 | N19: 1 | O19: 2026 | R19: =IF(wallet_records[[#This Row],[type]]="Gasto",wallet_records[[#This Row],[amount]]*(-1),wallet_records[[#This Row],[amount]]) -> -677400
A20: Fiducuenta ARU | B20: Intereses, ganancias de capital | C20: COP | D20: 83627.51 | E20: 83627.51 | F20: Ingreso | G20: Transferencia bancaria | H20: Rendimientos | I20: 46053.411 | J20: FALSE | M20: 31 | N20: 1 | O20: 2026 | R20: =IF(wallet_records[[#This Row],[type]]="Gasto",wallet_records[[#This Row],[amount]]*(-1),wallet_records[[#This Row],[amount]]) -> 83627.51
A21: Fidu Impuestos | B21: Intereses, ganancias de capital | C21: COP | D21: 122177.32 | E21: 122177.32 | F21: Ingreso | G21: Transferencia bancaria | H21: Rendimientos | I21: 46053.397 | J21: FALSE | M21: 31 | N21: 1 | O21: 2026 | R21: =IF(wallet_records[[#This Row],[type]]="Gasto",wallet_records[[#This Row],[amount]]*(-1),wallet_records[[#This Row],[amount]]) -> 122177.32
A22: Administración | B22: Intereses, ganancias de capital | C22: COP | D22: 37154.79 | E22: 37154.79 | F22: Ingreso | G22: Transferencia bancaria | H22: Rendimientos | I22: 46053.395 | J22: FALSE | M22: 31 | N22: 1 | O22: 2026 | R22: =IF(wallet_records[[#This Row],[type]]="Gasto",wallet_records[[#This Row],[amount]]*(-1),wallet_records[[#This Row],[amount]]) -> 37154.79
A23: Fidu Mantenimiento | B23: Intereses, ganancias de capital | C23: COP | D23: 26828.37 | E23: 26828.37 | F23: Ingreso | G23: Transferencia bancaria | H23: Rendimientos | I23: 46053.394 | J23: FALSE | M23: 31 | N23: 1 | O23: 2026 | R23: =IF(wallet_records[[#This Row],[type]]="Gasto",wallet_records[[#This Row],[amount]]*(-1),wallet_records[[#This Row],[amount]]) -> 26828.37
A24: Bancolombia | B24: Intereses, ganancias de capital | C24: COP | D24: 155217.34 | E24: 155217.34 | F24: Ingreso | G24: Transferencia bancaria | H24: Rendimientos | I24: 46024.364 | J24: FALSE | K24: Bancolombia | M24: 2 | N24: 1 | O24: 2026 | R24: =IF(wallet_records[[#This Row],[type]]="Gasto",wallet_records[[#This Row],[amount]]*(-1),wallet_records[[#This Row],[amount]]) -> 155217.34
A25: Bancolombia | B25: Intereses, ganancias de capital | C25: COP | D25: 32509.32 | E25: 32509.32 | F25: Ingreso | G25: Transferencia bancaria | H25: Rendimientos | I25: 46024.36 | J25: FALSE | K25: Bancolombia | M25: 2 | N25: 1 | O25: 2026 | R25: =IF(wallet_records[[#This Row],[type]]="Gasto",wallet_records[[#This Row],[amount]]*(-1),wallet_records[[#This Row],[amount]]) -> 32509.32
A26: Bancolombia | B26: Otros gastos administrativos | C26: COP | D26: 156000 | E26: 156000 | F26: Gasto | G26: Transferencia bancaria | H26: Pago de Administración | I26: 46068.5 | J26: FALSE | K26: Yari - Administrador | L26: Yari | M26: 15 | N26: 2 | O26: 2026 | R26: =IF(wallet_records[[#This Row],[type]]="Gasto",wallet_records[[#This Row],[amount]]*(-1),wallet_records[[#This Row],[amount]]) -> -156000
A27: Bancolombia | B27: Otros gastos administrativos | C27: COP | D27: 269400 | E27: 269400 | F27: Gasto | G27: Transferencia bancaria | H27: Pago de Administración | I27: 46068.5 | J27: FALSE | K27: Rivera del Valle - Administrador | L27: Rivera del Valle | M27: 15 | N27: 2 | O27: 2026 | R27: =IF(wallet_records[[#This Row],[type]]="Gasto",wallet_records[[#This Row],[amount]]*(-1),wallet_records[[#This Row],[amount]]) -> -269400
A28: Bancolombia | B28: Otros gastos administrativos | C28: COP | D28: 501542 | E28: 501542 | F28: Gasto | G28: Transferencia bancaria | H28: Pago de Administración | I28: 46068.5 | J28: FALSE | K28: Ocarinas - Administrador | L28: Ocarinas | M28: 15 | N28: 2 | O28: 2026 | R28: =IF(wallet_records[[#This Row],[type]]="Gasto",wallet_records[[#This Row],[amount]]*(-1),wallet_records[[#This Row],[amount]]) -> -501542
A29: Bancolombia | B29: Otros gastos administrativos | C29: COP | D29: 116800 | E29: 116800 | F29: Gasto | G29: Transferencia bancaria | H29: Campos de Paz | I29: 46041.5 | J29: FALSE | L29: Martha Lucía Uribe Jaramillo | M29: 19 | N29: 1 | O29: 2026 | R29: =IF(wallet_records[[#This Row],[type]]="Gasto",wallet_records[[#This Row],[amount]]*(-1),wallet_records[[#This Row],[amount]]) -> -116800
A30: Bancolombia | B30: Otros gastos administrativos | C30: COP | D30: 58000 | E30: 58000 | F30: Gasto | G30: Transferencia bancaria | H30: Fátima | I30: 46041.5 | J30: FALSE | L30: Martha Lucía Uribe Jaramillo | M30: 19 | N30: 1 | O30: 2026 | R30: =IF(wallet_records[[#This Row],[type]]="Gasto",wallet_records[[#This Row],[amount]]*(-1),wallet_records[[#This Row],[amount]]) -> -58000
A31: Bancolombia | B31: Otros gastos administrativos | C31: COP | D31: 501542 | E31: 501542 | F31: Gasto | G31: Transferencia bancaria | H31: Pago de Administración | I31: 46039.501 | J31: FALSE | K31: Ocarinas - Administrador | L31: Ocarinas | M31: 17 | N31: 1 | O31: 2026 | R31: =IF(wallet_records[[#This Row],[type]]="Gasto",wallet_records[[#This Row],[amount]]*(-1),wallet_records[[#This Row],[amount]]) -> -501542
A32: Bancolombia | B32: Otros gastos administrativos | C32: COP | D32: 156000 | E32: 156000 | F32: Gasto | G32: Efectivo | H32: Pago de Administración | I32: 46039.5 | J32: FALSE | K32: Yari - Administrador | L32: Yari | M32: 17 | N32: 1 | O32: 2026 | R32: =IF(wallet_records[[#This Row],[type]]="Gasto",wallet_records[[#This Row],[amount]]*(-1),wallet_records[[#This Row],[amount]]) -> -156000
A33: Bancolombia | B33: Otros gastos administrativos | C33: COP | D33: 269400 | E33: 269400 | F33: Gasto | G33: Transferencia bancaria | H33: Pago de Administración | I33: 46039.5 | J33: FALSE | K33: Rivera del Valle - Administrador | L33: Rivera del Valle | M33: 17 | N33: 1 | O33: 2026 | R33: =IF(wallet_records[[#This Row],[type]]="Gasto",wallet_records[[#This Row],[amount]]*(-1),wallet_records[[#This Row],[amount]]) -> -269400
A34: Bancolombia | B34: Otros gastos administrativos | C34: COP | D34: 2700 | E34: 2700 | F34: Gasto | G34: Efectivo | H34: Comisión retiro | I34: 46027.845 | J34: FALSE | M34: 5 | N34: 1 | O34: 2026 | R34: =IF(wallet_records[[#This Row],[type]]="Gasto",wallet_records[[#This Row],[amount]]*(-1),wallet_records[[#This Row],[amount]]) -> -2700
A35: Bancolombia | B35: Otros gastos administrativos | C35: COP | D35: 124600 | E35: 124600 | F35: Gasto | G35: Efectivo | H35: Fondos para gastos varios | I35: 46025.731 | J35: FALSE | M35: 3 | N35: 1 | O35: 2026 | R35: =IF(wallet_records[[#This Row],[type]]="Gasto",wallet_records[[#This Row],[amount]]*(-1),wallet_records[[#This Row],[amount]]) -> -124600
A36: Bancolombia | B36: Otros gastos administrativos | C36: COP | D36: 156860 | E36: 156860 | F36: Gasto | G36: Transferencia bancaria | H36: Fondos para gastos varios | I36: 46025.73 | J36: FALSE | M36: 3 | N36: 1 | O36: 2026 | R36: =IF(wallet_records[[#This Row],[type]]="Gasto",wallet_records[[#This Row],[amount]]*(-1),wallet_records[[#This Row],[amount]]) -> -156860
A37: Bancolombia | B37: Otros gastos administrativos | C37: COP | D37: 180000 | E37: 180000 | F37: Gasto | G37: Transferencia bancaria | H37: Fondos para gastos varios | I37: 46023.456 | J37: FALSE | L37: Martha Lucía Uribe Jaramillo | M37: 1 | N37: 1 | O37: 2026 | R37: =IF(wallet_records[[#This Row],[type]]="Gasto",wallet_records[[#This Row],[amount]]*(-1),wallet_records[[#This Row],[amount]]) -> -180000
A38: Bancolombia | B38: Reparaciones y mantenimiento | C38: COP | D38: 50000 | E38: 50000 | F38: Gasto | G38: Transferencia bancaria | H38: Mantenimiento | I38: 46067.4 | J38: FALSE | K38: Elmer Marin - Fontanero | L38: Yari | M38: 14 | N38: 2 | O38: 2026 | R38: =IF(wallet_records[[#This Row],[type]]="Gasto",wallet_records[[#This Row],[amount]]*(-1),wallet_records[[#This Row],[amount]]) -> -50000
A39: Bancolombia | B39: Reparaciones y mantenimiento | C39: COP | D39: 520000 | E39: 520000 | F39: Gasto | G39: Transferencia bancaria | H39: Mantenimiento | I39: 46064.372 | J39: FALSE | K39: Elmer Marin - Fontanero | L39: Yari | M39: 11 | N39: 2 | O39: 2026 | R39: =IF(wallet_records[[#This Row],[type]]="Gasto",wallet_records[[#This Row],[amount]]*(-1),wallet_records[[#This Row],[amount]]) -> -520000
A40: Bancolombia | B40: Reparaciones y mantenimiento | C40: COP | D40: 80500 | E40: 80500 | F40: Gasto | G40: Efectivo | H40: Mantenimiento | I40: 46063.371 | J40: FALSE | K40: Pisende | L40: Yari | M40: 10 | N40: 2 | O40: 2026 | R40: =IF(wallet_records[[#This Row],[type]]="Gasto",wallet_records[[#This Row],[amount]]*(-1),wallet_records[[#This Row],[amount]]) -> -80500
...

Sheet Activos
E5: Propiedad | F5: Avaluo catastral | G5: Avaluo Comercial | H5: Valor arriendo | M5: Impuesto predial | R5: Administracion
H6: 2022 | I6: 2023 | J6: 2024 | K6: 2025 | L6: 2026 | M6: 2022 | N6: 2023 | O6: 2024 | P6: 2025 | Q6: 2026 | R6: 2022 | S6: 2023 | T6: 2024 | U6: 2025 | V6: 2026
E7: Yari | F7: =260263000+11327000 -> 271590000 | G7: =(260263000+11327000)*1.4 -> 380226000 | H7: 1100000 | I7: 1350000 | J7: 1350000 | K7: 1650000 | N7: 1652293 | O7: 1926459 | P7: 2177825 | Q7: =P7*1.22 -> 2656946.5 | R7: 114000 | S7: 126000 | T7: 138000 | U7: 247500 | V7: =U7*1.237 -> 306157.5
E8: Belén | F8: 784665000 | G8: =784665000*1.4 -> 1098531000 | J8: 3000000 | K8: 3144600 | N8: 2905777 | O8: 3442766 | P8: 3904447 | Q8: =P8*1.22 -> 4763425.3 | V8: =U8*1.237 -> 0
E9: Ocarinas | F9: =168413000+20280000 -> 188693000 | G9: =(168413000+20280000)*1.4 -> 2.641702e+08 | H9: 980000 | I9: 1500000 | J9: 1400000 | K9: 1520000 | N9: 1442921 | O9: 1556970 | P9: 1613328 | Q9: =P9*1.22 -> 1968260.2 | R9: 314205 | S9: 393205 | T9: 437505 | U9: 477205 | V9: =U9*1.237 -> 590302.59
E10: Pedregal | F10: 130962000 | G10: =130962000*1.4 -> 183346800 | H10: 360000 | I10: 400000 | J10: 450000 | K10: 500000 | N10: 269629 | O10: 279068 | P10: 316495 | Q10: =P10*1.22 -> 386123.9 | V10: =U10*1.237 -> 0
E11: Ribera del valle | F11: =137811000+31940000 -> 169751000 | G11: =(137811000+31940000)*1.4 -> 2.376514e+08 | H11: 1200000 | I11: 1500000 | J11: 1630000 | K11: 1715000 | N11: 871419 | O11: 1032495 | P11: 1170958 | Q11: =P11*1.22 -> 1428568.8 | R11: 173200 | S11: 195900 | T11: 243000 | U11: 156300 | V11: =U11*1.237 -> 193343.1
E12: La Ceja | F12: 85100000 | G12: =85100000*1.4 -> 1.1914e+08 | H12: 225000 | I12: 881000 | J12: 881000 | K12: 881000 | M12: 550458 | N12: 765580 | O12: 911108 | P12: 765532 | Q12: =P12*1.22 -> 933949.04 | V12: =U12*1.237 -> 0
E13: Total | F13: =SUM(F7:F12) -> 1630761000 | G13: =SUM(G7:G12) -> 2283065400 | H13: =SUM(H7:H12) -> 3865000 | I13: =SUM(I7:I12) -> 5631000 | J13: =SUM(J7:J12) -> 8711000 | K13: =SUM(K7:K12) -> 9410600 | L13: =SUM(L7:L12) -> 0 | M13: =SUM(M7:M12) -> 550458 | ... P13: =SUM(P7:P12) -> 9948585 | Q13: =P13*1.22 -> 12137274 | R13: =SUM(R7:R12) -> 601405 | S13: =SUM(S7:S12) -> 715105 | T13: =SUM(T7:T12) -> 818505 | U13: =SUM(U7:U12) -> 881005 | V13: =SUM(V7:V12) -> 1089803.2
G14: Total Anualizado | H14: =H13*12 -> 46380000 | I14: =I13*12 -> 67572000 | J14: =J13*12 -> 104532000 | K14: =K13*12 -> 112927200 | L14: 0 | T14: =R13*12 -> 7216860 | U14: =S13*12 -> 8581260 | V14: =T13*12 -> 9822060 | W14: =U13*12 -> 10572060 | X14: =V13*12 -> 13077638
I17: Diciembre | O17: =(O7-N7)/N7 -> 0.16593062 | P17: =(P7-O7)/O7 -> 0.13048085 | Q17: =(Q7-P7)/P7 -> 0.22
I18: Noviembre | O18: =(O8-N8)/N8 -> 0.18480049 | P18: =(P8-O8)/O8 -> 0.13410177 | Q18: =(Q8-P8)/P8 -> 0.22
I19: Junio | O19: =(O9-N9)/N9 -> 0.079040363 | P19: =(P9-O9)/O9 -> 0.036197229 | Q19: =(Q9-P9)/P9 -> 0.22
O20: =(O10-N10)/N10 -> 0.035007362 | P20: =(P10-O10)/O10 -> 0.13411427 | Q20: =(Q10-P10)/P10 -> 0.22
O21: =(O11-N11)/N11 -> 0.18484334 | P21: =(P11-O11)/O11 -> 0.13410525 | Q21: =(Q11-P11)/P11 -> 0.22
O22: =(O12-N12)/N12 -> 0.19008856 | P22: =(P12-O12)/O12 -> -0.15977908 | Q22: =(Q12-P12)/P12 -> 0.22
G23: Mazda | H23: =4039975*1.1 -> 4443972.5
G24: Campos de Paz y Fatima | H24: =86600*1.1 -> 95260
G25: Taxi | H25: =2051498*1.1 -> 2256647.8
B29: Datos generales Ocarinas
B30: Municipio | C30: Medellin | F30: Históricos | G30: 2022 | H30: 2023 | I30: 2024 | J30: 2025 | K30: 2026 | L30: 2027
B31: Dirección | C31: Ocarinas PH Carrera 65 CC # 31 - 34
B32: Apartamento | C32: 205 | F32: Avalúo catastral | G32: =17500000+146744000 -> 164244000 | H32: =18254000+153069000 -> 171323000 | I32: =19689000+163508000 -> 183197000 | J32: =20280000+168413000 -> 188693000
B33: Parqueadero | C33: 99048 | H33: =(H32/G32)-1 -> 0.043100509 | I33: =(I32/H32)-1 -> 0.069307682 | J33: =(J32/I32)-1 -> 0.030000491
B34: Inquilino | C34: Jorge | F34: Avalúo comercial | G34: =G32*1.4 -> 229941600 | H34: =H32*1.4 -> 2.398522e+08 | I34: =I32*1.4 -> 2.564758e+08 | J34: =J32*1.4 -> 2.641702e+08
B35: Contacto | C35: 3003895464 | H35: =(H34/G34)-1 -> 0.043100509 | I35: =(I34/H34)-1 -> 0.069307682 | J35: =(J34/I34)-1 -> 0.030000491
B36: Inicio Contrato | F36: Arriendo | G36: 980000 | H36: 1500000 | I36: 1400000 | J36: 1520000 | K36: =J36*(1+K37) -> 1597520 | L36: =K36*(1+L37) -> 1693371.2
B37: Adminisrador | H37: =(H36/G36)-1 -> 0.53061224 | I37: =(I36/H36)-1 -> -0.066666667 | J37: =(J36/I36)-1 -> 0.085714286 | K37: 0.051 | L37: 0.06
B38: Contacto administrador | F38: Administración | G38: 314205 | H38: 393205 | I38: 437505 | J38: 477205 | K38: =J38*(1+K39) -> 590302.59 | L38: =K38*(1+L39) -> 678847.97
B39: Fecha pago administracion | H39: =(H38/G38)-1 -> 0.25142821 | I39: =(I38/H38)-1 -> 0.11266388 | J39: =(J38/I38)-1 -> 0.09074182 | K39: 0.237 | L39: 0.15
B40: Cuenta pago administacion | C40: 55194145283 Bancolombia ahorros | F40: Predial | G40: =1098724+111610 -> 1210334 | H40: 1442921 | I40: 1556970 | J40: 1613328 | K40: =J40*(1+K41) -> 1995686.7 | L40: =K40*(1+L41) -> 2295039.7
B41: Fecha pago canon de arriendo | C41: 18 de cada mes | H41: =(H40/G40)-1 -> 0.19216762 | I41: =(I40/H40)-1 -> 0.079040363 | J41: =(J40/I40)-1 -> 0.036197229 | K41: 0.237 | L41: 0.15
B42: Arriendo Anual | C42: 2026 | D42: =J36*5+K36*7 -> 18782640 | G42: =G40/G32 -> 0.0073691216 | H42: =H40/H32 -> 0.0084222259 | I42: =I40/I32 -> 0.0084988837 | J42: =J40/J32 -> 0.0085500151
B43: Arriendo Anual Ajustado | C43: =1/12 -> 0.083333333 | D43: =D42*(1-C43) -> 17217420
B44: Valor Administración | C44: 2026 | D44: =K38*12 -> 7083631
B45: Predial estimado | C45: 2026 | D45: =K40 -> 1995686.7
B48: Datos generales Rivera del Valle
B49: Municipio | D49: Medellin | F49: Históricos | G49: 2022 | H49: 2023 | I49: 2024 | J49: 2025 | K49: 2026 | L49: 2027
B50: Dirección | D50: Rivera del Valle Calle 60 #75-150
B51: Apartamento | D51: 11-643 | F51: Avalúo catastral | H51: =125255000+28750000 -> 154005000 | I51: =133797000+31010000 -> 164807000 | J51: =137811000+31940000 -> 169751000
...

Sheet Saldos
D2: Bancolombia | E2: Mantenimiento | F2: Impuestos | G2: Administración | H2: ARU | I2: Nu Bank | J2: Total | L2: Bancolombia | M2: Mantenimiento | N2: Impuestos | O2: ARU | P2: Nu Bank | Q2: Total | S2: Bancolombia | T2: Mantenimiento | U2: Impuestos | V2: ARU | W2: Nu Bank | X2: Total | Z2: Bancolombia | AA2: Mantenimiento | AB2: Impuestos | AC2: ARU | AD2: Nu Bank | AE2: Total
B3: Mes | C3: Año | D3: Saldo | E3: Saldo | F3: Saldo | G3: Saldo | H3: Saldo | I3: Saldo | J3: Saldo | L3: Diferencia | M3: Diferencia | N3: Diferencia | O3: Diferencia | P3: Diferencia | Q3: Diferencia | S3: Imputado | T3: Imputado | U3: Imputado | V3: Imputado | W3: Imputado | X3: Imputado | Z3: Ajuste | AA3: Ajuste | AB3: Ajuste | AC3: Ajuste | AD3: Ajuste | AE3: Ajuste
B4: 1 | C4: 2022 | D4: 8545970.5 | E4: 0 | F4: 0 | H4: 0 | I4: 0 | J4: =SUM(D4:I4) -> 8545970.5
B5: 2 | C5: 2022 | D5: 8552288.9 | E5: 0 | F5: 0 | H5: 0 | I5: 0 | J5: =SUM(D5:I5) -> 8552288.9
B6: 3 | C6: 2022 | D6: 7634668.6 | E6: 0 | F6: 0 | H6: 0 | I6: 0 | J6: =SUM(D6:I6) -> 7634668.6 | L6: =D6-D5 -> -917620.3 | M6: =E6-E5 -> 0 | N6: =F6-F5 -> 0 | O6: =H6-H5 -> 0 | P6: =I6-I5 -> 0 | Q6: =J6-J5 -> -917620.3 | S6: =SUMIFS(wallet_records!$R:$R,wallet_records!$A:$A,"Bancolombia",wallet_records!$N:$N,Saldos!$B6,wallet_records!$O:$O,Saldos!$C6) -> -917620.3 | T6: =SUMIFS(wallet_records!$R:$R,wallet_records!$A:$A,"Fidu Mantenimiento",wallet_records!$N:$N,Saldos!$B6,wallet_records!$O:$O,Saldos!$C6) -> 0 | U6: =SUMIFS(wallet_records!$R:$R,wallet_records!$A:$A,"Fidu Impuestos",wallet_records!$N:$N,Saldos!$B6,wallet_records!$O:$O,Saldos!$C6) -> 0 | V6: =SUMIFS(wallet_records!$R:$R,wallet_records!$A:$A,"Fiducuenta ARU",wallet_records!$N:$N,Saldos!$B6,wallet_records!$O:$O,Saldos!$C6) -> 0 | W6: =SUMIFS(wallet_records!$R:$R,wallet_records!$A:$A,"Nu Bank",wallet_records!$N:$N,Saldos!$B6,wallet_records!$O:$O,Saldos!$C6) -> 0 | X6: =SUM(S6:W6) -> -917620.3 | Z6: =L6-S6 -> 1.1641532e-09 | AA6: =M6-T6 -> 0 | AB6: =N6-U6 -> 0 | AC6: =O6-V6 -> 0 | AD6: =P6-W6 -> 0 | AE6: =SUM(Z6:AD6) -> 1.1641532e-09
B7: 4 | C7: 2022 | D7: 7332270.5 | E7: 0 | F7: 0 | H7: 0 | I7: 0 | J7: =SUM(D7:I7) -> 7332270.5 | L7: =D7-D6 -> -302398.05 | M7: =E7-E6 -> 0 | N7: =F7-F6 -> 0 | O7: =H7-H6 -> 0 | P7: =I7-I6 -> 0 | Q7: =J7-J6 -> -302398.05 | S7: =SUMIFS(wallet_records!$R:$R,wallet_records!$A:$A,"Bancolombia",wallet_records!$N:$N,Saldos!$B7,wallet_records!$O:$O,Saldos!$C7) -> -302398.05 | T7: =SUMIFS(wallet_records!$R:$R,wallet_records!$A:$A,"Fidu Mantenimiento",wallet_records!$N:$N,Saldos!$B7,wallet_records!$O:$O,Saldos!$C7) -> 0 | U7: =SUMIFS(wallet_records!$R:$R,wallet_records!$A:$A,"Fidu Impuestos",wallet_records!$N:$N,Saldos!$B7,wallet_records!$O:$O,Saldos!$C7) -> 0 | V7: =SUMIFS(wallet_records!$R:$R,wallet_records!$A:$A,"Fiducuenta ARU",wallet_records!$N:$N,Saldos!$B7,wallet_records!$O:$O,Saldos!$C7) -> 0 | W7: =SUMIFS(wallet_records!$R:$R,wallet_records!$A:$A,"Nu Bank",wallet_records!$N:$N,Saldos!$B7,wallet_records!$O:$O,Saldos!$C7) -> 0 | X7: =SUM(S7:W7) -> -302398.05 | Z7: =L7-S7 -> -9.3132257e-10 | AA7: =M7-T7 -> 0 | AB7: =N7-U7 -> 0 | AC7: =O7-V7 -> 0 | AD7: =P7-W7 -> 0 | AE7: =SUM(Z7:AD7) -> -9.3132257e-10
B8: 5 | C8: 2022 | D8: 8165035.1 | E8: 500000 | F8: 1562500 | H8: 0 | I8: 0 | J8: =SUM(D8:I8) -> 10227535 | L8: =D8-D7 -> 832764.58 | M8: =E8-E7 -> 500000 | N8: =F8-F7 -> 1562500 | O8: =H8-H7 -> 0 | P8: =I8-I7 -> 0 | Q8: =J8-J7 -> 2895264.6 | S8: =SUMIFS(wallet_records!$R:$R,wallet_records!$A:$A,"Bancolombia",wallet_records!$N:$N,Saldos!$B8,wallet_records!$O:$O,Saldos!$C8) -> 2895264.6 | T8: =SUMIFS(wallet_records!$R:$R,wallet_records!$A:$A,"Fidu Mantenimiento",wallet_records!$N:$N,Saldos!$B8,wallet_records!$O:$O,Saldos!$C8) -> 0 | U8: =SUMIFS(wallet_records!$R:$R,wallet_records!$A:$A,"Fidu Impuestos",wallet_records!$N:$N,Saldos!$B8,wallet_records!$O:$O,Saldos!$C8) -> 0 | V8: =SUMIFS(wallet_records!$R:$R,wallet_records!$A:$A,"Fiducuenta ARU",wallet_records!$N:$N,Saldos!$B8,wallet_records!$O:$O,Saldos!$C8) -> 0 | W8: =SUMIFS(wallet_records!$R:$R,wallet_records!$A:$A,"Nu Bank",wallet_records!$N:$N,Saldos!$B8,wallet_records!$O:$O,Saldos!$C8) -> 0 | X8: =SUM(S8:W8) -> 2895264.6 | Z8: =L8-S8 -> -2062500 | AA8: =M8-T8 -> 500000 | AB8: =N8-U8 -> 1562500 | AC8: =O8-V8 -> 0 | AD8: =P8-W8 -> 0 | AE8: =SUM(Z8:AD8) -> 0
B9: 6 | C9: 2022 | D9: 7027980.2 | E9: 901956 | F9: 3131111 | H9: 0 | I9: 0 | J9: =SUM(D9:I9) -> 11061047 | L9: =D9-D8 -> -1137054.9 | M9: =E9-E8 -> 401956 | N9: =F9-F8 -> 1568611 | O9: =H9-H8 -> 0 | P9: =I9-I8 -> 0 | Q9: =J9-J8 -> 833512.09 | S9: =SUMIFS(wallet_records!$R:$R,wallet_records!$A:$A,"Bancolombia",wallet_records!$N:$N,Saldos!$B9,wallet_records!$O:$O,Saldos!$C9) -> 875445.09 | T9: =SUMIFS(wallet_records!$R:$R,wallet_records!$A:$A,"Fidu Mantenimiento",wallet_records!$N:$N,Saldos!$B9,wallet_records!$O:$O,Saldos!$C9) -> -48044 | U9: =SUMIFS(wallet_records!$R:$R,wallet_records!$A:$A,"Fidu Impuestos",wallet_records!$N:$N,Saldos!$B9,wallet_records!$O:$O,Saldos!$C9) -> 6111 | V9: =SUMIFS(wallet_records!$R:$R,wallet_records!$A:$A,"Fiducuenta ARU",wallet_records!$N:$N,Saldos!$B9,wallet_records!$O:$O,Saldos!$C9) -> 0 | W9: =SUMIFS(wallet_records!$R:$R,wallet_records!$A:$A,"Nu Bank",wallet_records!$N:$N,Saldos!$B9,wallet_records!$O:$O,Saldos!$C9) -> 0 | X9: =SUM(S9:W9) -> 833512.09 | Z9: =L9-S9 -> -2012500 | AA9: =M9-T9 -> 450000 | AB9: =N9-U9 -> 1562500 | AC9: =O9-V9 -> 0 | AD9: =P9-W9 -> 0 | AE9: =SUM(Z9:AD9) -> 9.3132257e-10
B10: 7 | C10: 2022 | D10: 7321266.8 | E10: 1355484 | F10: 4705857 | H10: 0 | I10: 0 | J10: =SUM(D10:I10) -> 13382608 | L10: =D10-D9 -> 293286.57 | M10: =E10-E9 -> 453528 | N10: =F10-F9 -> 1574746 | O10: =H10-H9 -> 0 | P10: =I10-I9 -> 0 | Q10: =J10-J9 -> 2321560.6 | S10: =SUMIFS(wallet_records!$R:$R,wallet_records!$A:$A,"Bancolombia",wallet_records!$N:$N,Saldos!$B10,wallet_records!$O:$O,Saldos!$C10) -> 2305786.6 | T10: =SUMIFS(wallet_records!$R:$R,wallet_records!$A:$A,"Fidu Mantenimiento",wallet_records!$N:$N,Saldos!$B10,wallet_records!$O:$O,Saldos!$C10) -> 3528 | U10: =SUMIFS(wallet_records!$R:$R,wallet_records!$A:$A,"Fidu Impuestos",wallet_records!$N:$N,Saldos!$B10,wallet_records!$O:$O,Saldos!$C10) -> 12246 | V10: =SUMIFS(wallet_records!$R:$R,wallet_records!$A:$A,"Fiducuenta ARU",wallet_records!$N:$N,Saldos!$B10,wallet_records!$O:$O,Saldos!$C10) -> 0 | W10: =SUMIFS(wallet_records!$R:$R,wallet_records!$A:$A,"Nu Bank",wallet_records!$N:$N,Saldos!$B10,wallet_records!$O:$O,Saldos!$C10) -> 0 | X10: =SUM(S10:W10) -> 2321560.6 | Z10: =L10-S10 -> -2012500 | AA10: =M10-T10 -> 450000 | AB10: =N10-U10 -> 1562500 | AC10: =O10-V10 -> 0 | AD10: =P10-W10 -> 0 | AE10: =SUM(Z10:AD10) -> -9.3132257e-10
B11: 8 | C11: 2022 | D11: 5780011.8 | E11: 1811303 | F11: 6288560 | H11: 0 | I11: 0 | J11: =SUM(D11:I11) -> 13879875 | L11: =D11-D10 -> -1541255 | M11: =E11-E10 -> 455819 | N11: =F11-F10 -> 1582703 | O11: =H11-H10 -> 0 | P11: =I11-I10 -> 0 | Q11: =J11-J10 -> 497266.99 | S11: =SUMIFS(wallet_records!$R:$R,wallet_records!$A:$A,"Bancolombia",wallet_records!$N:$N,Saldos!$B11,wallet_records!$O:$O,Saldos!$C11) -> 471244.99 | T11: =SUMIFS(wallet_records!$R:$R,wallet_records!$A:$A,"Fidu Mantenimiento",wallet_records!$N:$N,Saldos!$B11,wallet_records!$O:$O,Saldos!$C11) -> 5819 | U11: =SUMIFS(wallet_records!$R:$R,wallet_records!$A:$A,"Fidu Impuestos",wallet_records!$N:$N,Saldos!$B11,wallet_records!$O:$O,Saldos!$C11) -> 20203 | V11: =SUMIFS(wallet_records!$R:$R,wallet_records!$A:$A,"Fiducuenta ARU",wallet_records!$N:$N,Saldos!$B11,wallet_records!$O:$O,Saldos!$C11) -> 0 | W11: =SUMIFS(wallet_records!$R:$R,wallet_records!$A:$A,"Nu Bank",wallet_records!$N:$N,Saldos!$B11,wallet_records!$O:$O,Saldos!$C11) -> 0 | X11: =SUM(S11:W11) -> 497266.99 | Z11: =L11-S11 -> -2012500 | AA11: =M11-T11 -> 450000 | AB11: =N11-U11 -> 1562500 | AC11: =O11-V11 -> 0 | AD11: =P11-W11 -> 0 | AE11: =SUM(Z11:AD11) -> 0
B12: 9 | C12: 2022 | D12: 2490748.8 | E12: 2270178 | F12: 7881873 | H12: 0 | I12: 0 | J12: =SUM(D12:I12) -> 12642800 | L12: =D12-D11 -> -3289263 | M12: =E12-E11 -> 458875 | N12: =F12-F11 -> 1593313 | O12: =H12-H11 -> 0 | P12: =I12-I11 -> 0 | Q12: =J12-J11 -> -1237075 | S12: =SUMIFS(wallet_records!$R:$R,wallet_records!$A:$A,"Bancolombia",wallet_records!$N:$N,Saldos!$B12,wallet_records!$O:$O,Saldos!$C12) -> -1276763 | T12: =SUMIFS(wallet_records!$R:$R,wallet_records!$A:$A,"Fidu Mantenimiento",wallet_records!$N:$N,Saldos!$B12,wallet_records!$O:$O,Saldos!$C12) -> 8875 | U12: =SUMIFS(wallet_records!$R:$R,wallet_records!$A:$A,"Fidu Impuestos",wallet_records!$N:$N,Saldos!$B12,wallet_records!$O:$O,Saldos!$C12) -> 30813 | V12: =SUMIFS(wallet_records!$R:$R,wallet_records!$A:$A,"Fiducuenta ARU",wallet_records!$N:$N,Saldos!$B12,wallet_records!$O:$O,Saldos!$C12) -> 0 | W12: =SUMIFS(wallet_records!$R:$R,wallet_records!$A:$A,"Nu Bank",wallet_records!$N:$N,Saldos!$B12,wallet_records!$O:$O,Saldos!$C12) -> 0 | X12: =SUM(S12:W12) -> -1237075 | Z12: =L12-S12 -> -2012500 | AA12: =M12-T12 -> 450000 | AB12: =N12-U12 -> 1562500 | AC12: =O12-V12 -> 0 | AD12: =P12-W12 -> 0 | AE12: =SUM(Z12:AD12) -> 0
B13: 10 | C13: 2022 | D13: 3348640.8 | E13: 2732330 | F13: 9486564 | H13: 0 | I13: 0 | J13: =SUM(D13:I13) -> 15567535 | L13: =D13-D12 -> 857892.05 | M13: =E13-E12 -> 462152 | N13: =F13-F12 -> 1604691 | O13: =H13-H12 -> 0 | P13: =I13-I12 -> 0 | Q13: =J13-J12 -> 2924735.1 | S13: =SUMIFS(wallet_records!$R:$R,wallet_records!$A:$A,"Bancolombia",wallet_records!$N:$N,Saldos!$B13,wallet_records!$O:$O,Saldos!$C13) -> 2870392 | T13: =SUMIFS(wallet_records!$R:$R,wallet_records!$A:$A,"Fidu Mantenimiento",wallet_records!$N:$N,Saldos!$B13,wallet_records!$O:$O,Saldos!$C13) -> 12152 | U13: =SUMIFS(wallet_records!$R:$R,wallet_records!$A:$A,"Fidu Impuestos",wallet_records!$N:$N,Saldos!$B13,wallet_records!$O:$O,Saldos!$C13) -> 42191 | V13: =SUMIFS(wallet_records!$R:$R,wallet_records!$A:$A,"Fiducuenta ARU",wallet_records!$N:$N,Saldos!$B13,wallet_records!$O:$O,Saldos!$C13) -> 0 | W13: =SUMIFS(wallet_records!$R:$R,wallet_records!$A:$A,"Nu Bank",wallet_records!$N:$N,Saldos!$B13,wallet_records!$O:$O,Saldos!$C13) -> 0 | X13: =SUM(S13:W13) -> 2924735 | Z13: =L13-S13 -> -2012500 | AA13: =M13-T13 -> 450000 | AB13: =N13-U13 -> 1562500 | AC13: =O13-V13 -> 0 | AD13: =P13-W13 -> 0 | AE13: =SUM(Z13:AD13) -> 4.6566129e-10
B14: 11 | C14: 2022 | D14: 3247667.9 | E14: 3196956 | F14: 11099846 | H14: 0 | I14: 500000 | J14: =SUM(D14:I14) -> 18044470 | L14: =D14-D13 -> -100972.87 | M14: =E14-E13 -> 464626 | N14: =F14-F13 -> 1613282 | O14: =H14-H13 -> 0 | P14: =I14-I13 -> 500000 | Q14: =J14-J13 -> 2476935.1 | S14: =SUMIFS(wallet_records!$R:$R,wallet_records!$A:$A,"Bancolombia",wallet_records!$N:$N,Saldos!$B14,wallet_records!$O:$O,Saldos!$C14) -> 1911527.1 | T14: =SUMIFS(wallet_records!$R:$R,wallet_records!$A:$A,"Fidu Mantenimiento",wallet_records!$N:$N,Saldos!$B14,wallet_records!$O:$O,Saldos!$C14) -> 14626 | U14: =SUMIFS(wallet_records!$R:$R,wallet_records!$A:$A,"Fidu Impuestos",wallet_records!$N:$N,Saldos!$B14,wallet_records!$O:$O,Saldos!$C14) -> 50782 | V14: =SUMIFS(wallet_records!$R:$R,wallet_records!$A:$A,"Fiducuenta ARU",wallet_records!$N:$N,Saldos!$B14,wallet_records!$O:$O,Saldos!$C14) -> 0 | W14: =SUMIFS(wallet_records!$R:$R,wallet_records!$A:$A,"Nu Bank",wallet_records!$N:$N,Saldos!$B14,wallet_records!$O:$O,Saldos!$C14) -> 500000 | X14: =SUM(S14:W14) -> 2476935.1 | Z14: =L14-S14 -> -2012500 | AA14: =M14-T14 -> 450000 | AB14: =N14-U14 -> 1562500 | AC14: =O14-V14 -> 0 | AD14: =P14-W14 -> 0 | AE14: =SUM(Z14:AD14) -> 0
B15: 12 | C15: 2022 | D15: 2169341.6 | E15: 3666466 | F15: 12730085 | H15: 0 | I15: 1003052 | J15: =SUM(D15:I15) -> 19568945 | L15: =D15-D14 -> -1078326.3 | M15: =E15-E14 -> 469510 | N15: =F15-F14 -> 1630239 | O15: =H15-H14 -> 0 | P15: =I15-I14 -> 503052 | Q15: =J15-J14 -> 1524474.7 | S15: =SUMIFS(wallet_records!$R:$R,wallet_records!$A:$A,"Bancolombia",wallet_records!$N:$N,Saldos!$B15,wallet_records!$O:$O,Saldos!$C15) -> 971673.67 | T15: =SUMIFS(wallet_records!$R:$R,wallet_records!$A:$A,"Fidu Mantenimiento",wallet_records!$N:$N,Saldos!$B15,wallet_records!$O:$O,Saldos!$C15) -> 19510 | U15: =SUMIFS(wallet_records!$R:$R,wallet_records!$A:$A,"Fidu Impuestos",wallet_records!$N:$N,Saldos!$B15,wallet_records!$O:$O,Saldos!$C15) -> 30239 | V15: =SUMIFS(wallet_records!$R:$R,wallet_records!$A:$A,"Fiducuenta ARU",wallet_records!$N:$N,Saldos!$B15,wallet_records!$O:$O,Saldos!$C15) -> 0 | W15: =SUMIFS(wallet_records!$R:$R,wallet_records!$A:$A,"Nu Bank",wallet_records!$N:$N,Saldos!$B15,wallet_records!$O:$O,Saldos!$C15) -> 503052 | X15: =SUM(S15:W15) -> 1524474.7 | Z15: =L15-S15 -> -2050000 | AA15: =M15-T15 -> 450000 | AB15: =N15-U15 -> 1600000 | AC15: =O15-V15 -> 0 | AD15: =P15-W15 -> 0 | AE15: =SUM(Z15:AD15) -> 0
B16: 1 | C16: 2023 | D16: 1808563.3 | E16: 4113189 | F16: 14422866 | H16: 0 | I16: 1510362 | J16: =SUM(D16:I16) -> 21854980 | L16: =D16-D15 -> -360778.35 | M16: =E16-E15 -> 446723 | N16: =F16-F15 -> 1692781 | O16: =H16-H15 -> 0 | P16: =I16-I15 -> 507310 | Q16: =J16-J15 -> 2286035.6 | S16: =SUMIFS(wallet_records!$R:$R,wallet_records!$A:$A,"Bancolombia",wallet_records!$N:$N,Saldos!$B16,wallet_records!$O:$O,Saldos!$C16) -> 1689221.6 | T16: =SUMIFS(wallet_records!$R:$R,wallet_records!$A:$A,"Fidu Mantenimiento",wallet_records!$N:$N,Saldos!$B16,wallet_records!$O:$O,Saldos!$C16) -> -3277 | U16: =SUMIFS(wallet_records!$R:$R,wallet_records!$A:$A,"Fidu Impuestos",wallet_records!$N:$N,Saldos!$B16,wallet_records!$O:$O,Saldos!$C16) -> 92781 | V16: =SUMIFS(wallet_records!$R:$R,wallet_records!$A:$A,"Fiducuenta ARU",wallet_records!$N:$N,Saldos!$B16,wallet_records!$O:$O,Saldos!$C16) -> 0 | W16: =SUMIFS(wallet_records!$R:$R,wallet_records!$A:$A,"Nu Bank",wallet_records!$N:$N,Saldos!$B16,wallet_records!$O:$O,Saldos!$C16) -> 507310 | X16: =SUM(S16:W16) -> 2286035.6 | Z16: =L16-S16 -> -2050000 | AA16: =M16-T16 -> 450000 | AB16: =N16-U16 -> 1600000 | AC16: =O16-V16 -> 0 | AD16: =P16-W16 -> 0 | AE16: =SUM(Z16:AD16) -> 2.3283064e-10
B17: 2 | C17: 2023 | D17: 9770944 | E17: 4626180 | F17: 4982392 | H17: 0 | I17: 2646478 | J17: =SUM(D17:I17) -> 22025994 | L17: =D17-D16 -> 7962380.7 | M17: =E17-E16 -> 512991 | N17: =F17-F16 -> -9440474 | O17: =H17-H16 -> 0 | P17: =I17-I16 -> 1136116 | Q17: =J17-J16 -> 171013.73 | S17: =SUMIFS(wallet_records!$R:$R,wallet_records!$A:$A,"Bancolombia",wallet_records!$N:$N,Saldos!$B17,wallet_records!$O:$O,Saldos!$C17) -> 10012381 | T17: =SUMIFS(wallet_records!$R:$R,wallet_records!$A:$A,"Fidu Mantenimiento",wallet_records!$N:$N,Saldos!$B17,wallet_records!$O:$O,Saldos!$C17) -> 62991 | U17: =SUMIFS(wallet_records!$R:$R,wallet_records!$A:$A,"Fidu Impuestos",wallet_records!$N:$N,Saldos!$B17,wallet_records!$O:$O,Saldos!$C17) -> -11040474 | V17: =SUMIFS(wallet_records!$R:$R,wallet_records!$A:$A,"Fiducuenta ARU",wallet_records!$N:$N,Saldos!$B17,wallet_records!$O:$O,Saldos!$C17) -> 0 | W17: =SUMIFS(wallet_records!$R:$R,wallet_records!$A:$A,"Nu Bank",wallet_records!$N:$N,Saldos!$B17,wallet_records!$O:$O,Saldos!$C17) -> 1136116 | X17: =SUM(S17:W17) -> 171013.73 | Z17: =L17-S17 -> -2050000 | AA17: =M17-T17 -> 450000 | AB17: =N17-U17 -> 1600000 | AC17: =O17-V17 -> 0 | AD17: =P17-W17 -> 0 | AE17: =SUM(Z17:AD17) -> 0
... B51: 12 | C51: 2025 | D51: 4112943.4 | E51: 5263268 | F51: 24828736 | H51: 14238316 | I51: 32246510 | J51: =SUM(D51:I51) -> 80689773 | L51: =D51-D50 -> -1827410.7 | M51: =E51-E50 -> -849486 | N51: =F51-F50 -> 711176 | O51: =H51-H50 -> 1037491.3 | P51: =I51-I50 -> 5303061 | Q51: =J51-J50 -> 4374831.5 | S51: =SUMIFS(wallet_records!$R:$R,wallet_records!$A:$A,"Bancolombia",wallet_records!$N:$N,Saldos!$B51,wallet_records!$O:$O,Saldos!$C51) -> -1827410.7 | T51: =SUMIFS(wallet_records!$R:$R,wallet_records!$A:$A,"Fidu Mantenimiento",wallet_records!$N:$N,Saldos!$B51,wallet_records!$O:$O,Saldos!$C51) -> -849486 | U51: =SUMIFS(wallet_records!$R:$R,wallet_records!$A:$A,"Fidu Impuestos",wallet_records!$N:$N,Saldos!$B51,wallet_records!$O:$O,Saldos!$C51) -> 711176 | V51: =SUMIFS(wallet_records!$R:$R,wallet_records!$A:$A,"Fiducuenta ARU",wallet_records!$N:$N,Saldos!$B51,wallet_records!$O:$O,Saldos!$C51) -> 1037491.3 | W51: =SUMIFS(wallet_records!$R:$R,wallet_records!$A:$A,"Nu Bank",wallet_records!$N:$N,Saldos!$B51,wallet_records!$O:$O,Saldos!$C51) -> 5303061 | X51: =SUM(S51:W51) -> 4374831.5 | Z51: =L51-S51 -> 0 | AA51: =M51-T51 -> 0 | AB51: =N51-U51 -> 0 | AC51: =O51-V51 -> -1.1641532e-09 | AD51: =P51-W51 -> 0 | AE51: =SUM(Z51:AD51) -> -1.1641532e-09
B52: 1 | C52: 2026 | D52: 21288892 | E52: 5322606.4 | F52: 14349590 | G52: 14088855 | H52: 15321943 | I52: 0 | J52: =SUM(D52:H52) -> 70371886 | L52: =J52-J51 -> -10317887 | Z52: =SUM(Z6:Z51) -> -24387500 | AA52: =SUM(AA6:AA51) -> 6050000 | AB52: =SUM(AB6:AB51) -> 18937500 | AC52: =SUM(AC6:AC51) -> -4.6566129e-10 | AD52: =SUM(AD6:AD51) -> -1.0477379e-09 | AE52: =SUM(AE6:AE51) -> 600000
B53: 2 | C53: 2026 | D53: 11288892 | E53: 5322606.4 | F53: 14349590 | G53: 14088855 | H53: 16321943 | I53: 0 | J53: =SUM(D53:H53) -> 61371886
B54: 3 | C54: 2026 | I54: 0 | J54: =SUM(D54:H54) -> 0
B55: 4 | C55: 2026 | I55: 0 | J55: =SUM(D55:H55) -> 0
B56: 5 | C56: 2026 | I56: 0 | J56: =SUM(D56:H56) -> 0
B57: 6 | C57: 2026 | I57: 0 | J57: =SUM(D57:H57) -> 0
B58: 7 | C58: 2026 | I58: 0 | J58: =SUM(D58:H58) -> 0
B59: 8 | C59: 2026 | I59: 0 | J59: =SUM(D59:H59) -> 0
B60: 9 | C60: 2026 | I60: 0 | J60: =SUM(D60:H60) -> 0
B61: 10 | C61: 2026 | I61: 0 | J61: =SUM(D61:H61) -> 0
B62: 11 | C62: 2026 | I62: 0 | J62: =SUM(D62:H62) -> 0
B63: 12 | C63: 2026 | I63: 0 | J63: =SUM(D63:H63) -> 0

Sheet Presupuesto
B1: 156000
B2: 590302.59
B3: 317043.1 | D3: 46023 | F3: 46054 | H3: 46082 | J3: 46113 | L3: 46143 | N3: 46174 | P3: 46204 | R3: 46235 | T3: 46266 | V3: 46296 | X3: 46327 | Z3: 46357 | AB3: Acumulado 2026 | AE3: 46388 | AG3: 46419 | AI3: 46447 | AK3: 46478 | AM3: 46508 | AO3: 46539 | AQ3: 46569 | AS3: 46600 | AU3: 46631 | AW3: 46661 | AY3: 46692 | BA3: 46722 | BC3: Acumulado 2027
C5: Yari | D5: =E5/$E$11 -> 0.18264304 | E5: =Activos!$K$131 -> 1734150 | F5: =G5/$G$11 -> 0.18264304 | G5: =Activos!$K$131 -> 1734150 | H5: =I5/$I$11 -> 0.18264304 | I5: =Activos!$K$131 -> 1734150 | J5: =K5/$K$11 -> 0.18264304 | K5: =Activos!$K$131 -> 1734150 | L5: =M5/$M$11 -> 0.18264304 | M5: =Activos!$K$131 -> 1734150 | N5: =O5/$O$11 -> 0.17428205 | O5: =Activos!$K$131 -> 1734150 | P5: =Q5/$Q$11 -> 0.16901018 | Q5: =Activos!$K$131 -> 1734150 | R5: =S5/$S$11 -> 0.16827331 | S5: =Activos!$K$131 -> 1734150 | T5: =U5/$U$11 -> 0.16827331 | U5: =Activos!$K$131 -> 1734150 | V5: =W5/$W$11 -> 0.16827331 | W5: =Activos!$K$131 -> 1734150 | X5: =Y5/$Y$11 -> 0.16827331 | Y5: =Activos!$K$131 -> 1734150 | Z5: =AA5/$AA$11 -> 0.16685717 | AA5: =Activos!$K$131 -> 1734150 | AB5: =AC5/$AC$11 -> 0.17443272 | AC5: =E5+G5+I5+K5+M5+O5+Q5+S5+U5+W5+Y5+AA5 -> 20809800 | AE5: =AF5/$AF$11 -> 0.18391941 | AF5: =Activos!$L$131 -> 1838199 | AG5: =AH5/$AH$11 -> 0.18391941 | AH5: =Activos!$L$131 -> 1838199 | AI5: =AJ5/$AJ$11 -> 0.18391941 | AJ5: =Activos!$L$131 -> 1838199 | AK5: =AL5/$AL$11 -> 0.18391941 | AL5: =Activos!$L$131 -> 1838199 | AM5: =AN5/$AN$11 -> 0.18391941 | AN5: =Activos!$L$131 -> 1838199 | AO5: =AP5/$AP$11 -> 0.18217232 | AP5: =Activos!$L$131 -> 1838199 | AQ5: =AR5/$AR$11 -> 0.17866125 | AR5: =Activos!$L$131 -> 1838199 | AS5: =AT5/$AT$11 -> 0.17770172 | AT5: =Activos!$L$131 -> 1838199 | AU5: =AV5/$AV$11 -> 0.17770172 | AV5: =Activos!$L$131 -> 1838199 | AW5: =AX5/$AX$11 -> 0.17770172 | AX5: =Activos!$L$131 -> 1838199 | AY5: =AZ5/$AZ$11 -> 0.17770172 | AZ5: =Activos!$L$131 -> 1838199 | BA5: =BB5/$BB$11 -> 0.1753342 | BB5: =Activos!$L$131 -> 1838199 | BC5: =BD5/$BD$11 -> 0.18049092 | BD5: =AF5+AH5+AJ5+AL5+AN5+AP5+AR5+AT5+AV5+AX5+AZ5+BB5 -> 22058388
C6: Belén | D6: =E6/$E$11 -> 0.33119355 | E6: =Activos!$J$112 -> 3144600 | F6: =G6/$G$11 -> 0.33119355 | G6: =Activos!$J$112 -> 3144600 | H6: =I6/$I$11 -> 0.33119355 | I6: =Activos!$J$112 -> 3144600 | J6: =K6/$K$11 -> 0.33119355 | K6: =Activos!$J$112 -> 3144600 | L6: =M6/$M$11 -> 0.33119355 | M6: =Activos!$J$112 -> 3144600 | N6: =O6/$O$11 -> 0.31603226 | O6: =Activos!$J$112 -> 3144600 | P6: =Q6/$Q$11 -> 0.32210267 | Q6: =Activos!$K$112 -> 3304974.6 | R6: =S6/$S$11 -> 0.32069834 | S6: =Activos!$K$112 -> 3304974.6 | T6: =U6/$U$11 -> 0.32069834 | U6: =Activos!$K$112 -> 3304974.6 | V6: =W6/$W$11 -> 0.32069834 | W6: =Activos!$K$112 -> 3304974.6 | X6: =Y6/$Y$11 -> 0.32069834 | Y6: =Activos!$K$112 -> 3304974.6 | Z6: =AA6/$AA$11 -> 0.31799943 | AA6: =Activos!$K$112 -> 3304974.6 | AB6: =AC6/$AC$11 -> 0.32437125 | AC6: =E6+G6+I6+K6+M6+O6+Q6+S6+U6+W6+Y6+AA6 -> 38697448 | AE6: =AF6/$AF$11 -> 0.33067637 | AF6: =Activos!$K$112 -> 3304974.6 | AG6: =AH6/$AH$11 -> 0.33067637 | AH6: =Activos!$K$112 -> 3304974.6 | AI6: =AJ6/$AJ$11 -> 0.33067637 | AJ6: =Activos!$K$112 -> 3304974.6 | AK6: =AL6/$AL$11 -> 0.33067637 | AL6: =Activos!$K$112 -> 3304974.6 | AM6: =AN6/$AN$11 -> 0.33067637 | AN6: =Activos!$K$112 -> 3304974.6 | AO6: =AP6/$AP$11 -> 0.32753521 | AP6: =Activos!$K$112 -> 3304974.6 | AQ6: =AR6/$AR$11 -> 0.34049585 | AR6: =Activos!$L$112 -> 3503273.1 | AS6: =AT6/$AT$11 -> 0.33866716 | AT6: =Activos!$L$112 -> 3503273.1 | AU6: =AV6/$AV$11 -> 0.33866716 | AV6: =Activos!$L$112 -> 3503273.1 | AW6: =AX6/$AX$11 -> 0.33866716 | AX6: =Activos!$L$112 -> 3503273.1 | AY6: =AZ6/$AZ$11 -> 0.33866716 | AZ6: =Activos!$L$112 -> 3503273.1 | BA6: =BB6/$BB$11 -> 0.3341551 | BB6: =Activos!$L$112 -> 3503273.1 | BC6: =BD6/$BD$11 -> 0.33424752 | BD6: =AF6+AH6+AJ6+AL6+AN6+AP6+AR6+AT6+AV6+AX6+AZ6+BB6 -> 40849486
C7: Ocarinas | D7: =E7/$E$11 -> 0.16008847 | E7: =Activos!$J$36 -> 1520000 | F7: =G7/$G$11 -> 0.16008847 | G7: =Activos!$J$36 -> 1520000 | H7: =I7/$I$11 -> 0.16008847 | I7: =Activos!$J$36 -> 1520000 | J7: =K7/$K$11 -> 0.16008847 | K7: =Activos!$J$36 -> 1520000 | L7: =M7/$M$11 -> 0.16008847 | M7: =Activos!$J$36 -> 1520000 | N7: =O7/$O$11 -> 0.19597498 | O7: 1950000 | P7: =Q7/$Q$11 -> 0.2046659 | Q7: 2100000 | R7: =S7/$S$11 -> 0.20377358 | S7: 2100000 | T7: =U7/$U$11 -> 0.20377358 | U7: 2100000 | V7: =W7/$W$11 -> 0.20377358 | W7: 2100000 | X7: =Y7/$Y$11 -> 0.20377358 | Y7: 2100000 | Z7: =AA7/$AA$11 -> 0.20205868 | AA7: 2100000 | AB7: =AC7/$AC$11 -> 0.18566659 | AC7: =E7+G7+I7+K7+M7+O7+Q7+S7+U7+W7+Y7+AA7 -> 22150000 | AE7: =AF7/$AF$11 -> 0.15983848 | AF7: =Activos!$K$36 -> 1597520 | AG7: =AH7/$AH$11 -> 0.15983848 | AH7: =Activos!$K$36 -> 1597520 | AI7: =AJ7/$AJ$11 -> 0.15983848 | AJ7: =Activos!$K$36 -> 1597520 | AK7: =AL7/$AL$11 -> 0.15983848 | AL7: =Activos!$K$36 -> 1597520 | AM7: =AN7/$AN$11 -> 0.15983848 | AN7: =Activos!$K$36 -> 1597520 | AO7: =AP7/$AP$11 -> 0.16781935 | AP7: =Activos!$L$36 -> 1693371.2 | AQ7: =AR7/$AR$11 -> 0.16458491 | AR7: =Activos!$L$36 -> 1693371.2 | AS7: =AT7/$AT$11 -> 0.16370098 | AT7: =Activos!$L$36 -> 1693371.2 | AU7: =AV7/$AV$11 -> 0.16370098 | AV7: =Activos!$L$36 -> 1693371.2 | AW7: =AX7/$AX$11 -> 0.16370098 | AX7: =Activos!$L$36 -> 1693371.2 | AY7: =AZ7/$AZ$11 -> 0.16370098 | AZ7: =Activos!$L$36 -> 1693371.2 | BA7: =BB7/$BB$11 -> 0.16151999 | BB7: =Activos!$L$36 -> 1693371.2 | BC7: =BD7/$BD$11 -> 0.16234895 | BD7: =AF7+AH7+AJ7+AL7+AN7+AP7+AR7+AT7+AV7+AX7+AZ7+BB7 -> 19841198
C8: Pedregal | D8: =E8/$E$11 -> 0.052660681 | E8: =Activos!$J$93 -> 500000 | F8: =G8/$G$11 -> 0.052660681 | G8: =Activos!$J$93 -> 500000 | H8: =I8/$I$11 -> 0.052660681 | I8: =Activos!$J$93 -> 500000 | J8: =K8/$K$11 -> 0.052660681 | K8: =Activos!$J$93 -> 500000 | L8: =M8/$M$11 -> 0.052660681 | M8: =Activos!$J$93 -> 500000 | N8: =O8/$O$11 -> 0.052812743 | O8: =Activos!$K$93 -> 525500 | P8: =Q8/$Q$11 -> 0.051215206 | Q8: 525500 | R8: =S8/$S$11 -> 0.050991914 | S8: 525500 | T8: =U8/$U$11 -> 0.050991914 | U8: 525500 | V8: =W8/$W$11 -> 0.050991914 | W8: 525500 | X8: =Y8/$Y$11 -> 0.050991914 | Y8: 525500 | Z8: =AA8/$AA$11 -> 0.050562779 | AA8: 525500 | AB8: =AC8/$AC$11 -> 0.051789664 | AC8: =E8+G8+I8+K8+M8+O8+Q8+S8+U8+W8+Y8+AA8 -> 6178500 | AE8: =AF8/$AF$11 -> 0.052578447 | AF8: =Activos!$K$93 -> 525500 | AG8: =AH8/$AH$11 -> 0.052578447 | AH8: =Activos!$K$93 -> 525500 | AI8: =AJ8/$AJ$11 -> 0.052578447 | AJ8: =Activos!$K$93 -> 525500 | AK8: =AL8/$AL$11 -> 0.052578447 | AL8: =Activos!$K$93 -> 525500 | AM8: =AN8/$AN$11 -> 0.052578447 | AN8: =Activos!$K$93 -> 525500 | AO8: =AP8/$AP$11 -> 0.052078993 | AP8: =Activos!$K$93 -> 525500 | AQ8: =AR8/$AR$11 -> 0.051075257 | AR8: =Activos!$K$93 -> 525500 | AS8: =AT8/$AT$11 -> 0.050800948 | AT8: =Activos!$K$93 -> 525500 | AU8: =AV8/$AV$11 -> 0.050800948 | AV8: =Activos!$K$93 -> 525500 | AW8: =AX8/$AX$11 -> 0.050800948 | AX8: =Activos!$K$93 -> 525500 | AY8: =AZ8/$AZ$11 -> 0.050800948 | AZ8: =Activos!$K$93 -> 525500 | BA8: =BB8/$BB$11 -> 0.053131575 | BB8: =Activos!$L$93 -> 557030 | BC8: =BD8/$BD$11 -> 0.051856311 | BD8: =AF8+AH8+AJ8+AL8+AN8+AP8+AR8+AT8+AV8+AX8+AZ8+BB8 -> 6337530
C9: Rivera del Valle | D9: =E9/$E$11 -> 0.18062614 | E9: =Activos!$J$55 -> 1715000 | F9: =G9/$G$11 -> 0.18062614 | G9: =Activos!$J$55 -> 1715000 | H9: =I9/$I$11 -> 0.18062614 | I9: =Activos!$J$55 -> 1715000 | J9: =K9/$K$11 -> 0.18062614 | K9: =Activos!$J$55 -> 1715000 | L9: =M9/$M$11 -> 0.18062614 | M9: =Activos!$J$55 -> 1715000 | N9: =O9/$O$11 -> 0.17235748 | O9: =Activos!$J$55 -> 1715000 | P9: =Q9/$Q$11 -> 0.16714382 | Q9: =Activos!$J$55 -> 1715000 | R9: =S9/$S$11 -> 0.16641509 | S9: =Activos!$J$55 -> 1715000 | T9: =U9/$U$11 -> 0.16641509 | U9: =Activos!$J$55 -> 1715000 | V9: =W9/$W$11 -> 0.16641509 | W9: =Activos!$J$55 -> 1715000 | X9: =Y9/$Y$11 -> 0.16641509 | Y9: =Activos!$J$55 -> 1715000 | Z9: =AA9/$AA$11 -> 0.17343033 | AA9: =Activos!$K$55 -> 1802465 | AB9: =AC9/$AC$11 -> 0.17323963 | AC9: =E9+G9+I9+K9+M9+O9+Q9+S9+U9+W9+Y9+AA9 -> 20667465 | AE9: =AF9/$AF$11 -> 0.18034407 | AF9: =Activos!$K$55 -> 1802465 | AG9: =AH9/$AH$11 -> 0.18034407 | AH9: =Activos!$K$55 -> 1802465 | AI9: =AJ9/$AJ$11 -> 0.18034407 | AJ9: =Activos!$K$55 -> 1802465 | AK9: =AL9/$AL$11 -> 0.18034407 | AL9: =Activos!$K$55 -> 1802465 | AM9: =AN9/$AN$11 -> 0.18034407 | AN9: =Activos!$K$55 -> 1802465 | AO9: =AP9/$AP$11 -> 0.17863095 | AP9: =Activos!$K$55 -> 1802465 | AQ9: =AR9/$AR$11 -> 0.17518813 | AR9: =Activos!$K$55 -> 1802465 | AS9: =AT9/$AT$11 -> 0.17424725 | AT9: =Activos!$K$55 -> 1802465 | AU9: =AV9/$AV$11 -> 0.17424725 | AV9: =Activos!$K$55 -> 1802465 | AW9: =AX9/$AX$11 -> 0.17424725 | AX9: =Activos!$K$55 -> 1802465 | AY9: =AZ9/$AZ$11 -> 0.17424725 | AZ9: =Activos!$K$55 -> 1802465 | BA9: =BB9/$BB$11 -> 0.1822413 | BB9: =Activos!$L$55 -> 1910612.9 | BC9: =BD9/$BD$11 -> 0.17786715 | BD9: =AF9+AH9+AJ9+AL9+AN9+AP9+AR9+AT9+AV9+AX9+AZ9+BB9 -> 21737728
C10: La Ceja | D10: =E10/$E$11 -> 0.09278812 | E10: =Activos!$J$74 -> 881000 | F10: =G10/$G$11 -> 0.09278812 | G10: =Activos!$J$74 -> 881000 | H10: =I10/$I$11 -> 0.09278812 | I10: =Activos!$J$74 -> 881000 | J10: =K10/$K$11 -> 0.09278812 | K10: =Activos!$J$74 -> 881000 | L10: =M10/$M$11 -> 0.09278812 | M10: =Activos!$J$74 -> 881000 | N10: =O10/$O$11 -> 0.088540489 | O10: =Activos!$J$74 -> 881000 | P10: =Q10/$Q$11 -> 0.085862219 | Q10: =Activos!$J$74 -> 881000 | R10: =S10/$S$11 -> 0.089847752 | S10: =Activos!$K$74 -> 925931 | T10: =U10/$U$11 -> 0.089847752 | U10: =Activos!$K$74 -> 925931 | V10: =W10/$W$11 -> 0.089847752 | W10: =Activos!$K$74 -> 925931 | X10: =Y10/$Y$11 -> 0.089847752 | Y10: =Activos!$K$74 -> 925931 | Z10: =AA10/$AA$11 -> 0.089091616 | AA10: =Activos!$K$74 -> 925931 | AB10: =AC10/$AC$11 -> 0.090500142 | AC10: =E10+G10+I10+K10+M10+O10+Q10+S10+U10+W10+Y10+AA10 -> 10796655 | AE10: =AF10/$AF$11 -> 0.092643224 | AF10: =Activos!$K$74 -> 925931 | AG10: =AH10/$AH$11 -> 0.092643224 | AH10: =Activos!$K$74 -> 925931 | AI10: =AJ10/$AJ$11 -> 0.092643224 | AJ10: =Activos!$K$74 -> 925931 | AK10: =AL10/$AL$11 -> 0.092643224 | AL10: =Activos!$K$74 -> 925931 | AM10: =AN10/$AN$11 -> 0.092643224 | AN10: =Activos!$K$74 -> 925931 | AO10: =AP10/$AP$11 -> 0.091763186 | AP10: =Activos!$K$74 -> 925931 | AQ10: =AR10/$AR$11 -> 0.089994602 | AR10: =Activos!$K$74 -> 925931 | AS10: =AT10/$AT$11 -> 0.094881947 | AT10: =Activos!$L$74 -> 981486.86 | AU10: =AV10/$AV$11 -> 0.094881947 | AV10: =Activos!$L$74 -> 981486.86 | AW10: =AX10/$AX$11 -> 0.094881947 | AX10: =Activos!$L$74 -> 981486.86 | AY10: =AZ10/$AZ$11 -> 0.094881947 | AZ10: =Activos!$L$74 -> 981486.86 | BA10: =BB10/$BB$11 -> 0.093617835 | BB10: =Activos!$L$74 -> 981486.86 | BC10: =BD10/$BD$11 -> 0.093189146 | BD10: =AF10+AH10+AJ10+AL10+AN10+AP10+AR10+AT10+AV10+AX10+AZ10+BB10 -> 11388951
B11: ARRIENDOS | D11: =SUM(D5:D10) -> 1 | E11: =SUM(E5:E10) -> 9494750 | F11: =SUM(F5:F10) -> 1 | G11: =SUM(G5:G10) -> 9494750 | H11: =SUM(H5:H10) -> 1 | I11: =SUM(I5:I10) -> 9494750 | J11: =SUM(J5:J10) -> 1 | K11: =SUM(K5:K10) -> 9494750 | ... AB11: =SUM(AB5:AB10) -> 1 | AC11: =E11+G11+I11+K11+M11+O11+Q11+S11+U11+W11+Y11+AA11 -> 1.1929987e+08 | AE11: =SUM(AE5:AE10) -> 1 | AF11: =SUM(AF5:AF10) -> 9994589.6 | AG11: =SUM(AG5:AG10) -> 1 | AH11: =SUM(AH5:AH10) -> 9994589.6 | AI11: =SUM(AI5:AI10) -> 1 | AJ11: =SUM(AJ5:AJ10) -> 9994589.6 | AK11: =SUM(AK5:AK10) -> 1 | AL11: =SUM(AL5:AL10) -> 9994589.6 | ... BC11: =SUM(BC5:BC10) -> 1 | BD11: =AF11+AH11+AJ11+AL11+AN11+AP11+AR11+AT11+AV11+AX11+AZ11+BB11 -> 1.2221328e+08
B13: =Activos!K135 -> 2693969.5 | C13: Yari | D13: =E13/E5 -> 0.12945677 | E13: =$B13/12 -> 224497.46 | F13: =G13/G5 -> 0.12945677 | G13: =$B13/12 -> 224497.46 | H13: =I13/I5 -> 0.12945677 | I13: =$B13/12 -> 224497.46 | J13: =K13/K5 -> 0.12945677 | K13: =$B13/12 -> 224497.46 | L13: =M13/M5 -> 0.12945677 | M13: =$B13/12 -> 224497.46 | N13: =O13/O5 -> 0.12945677 | O13: =$B13/12 -> 224497.46 | P13: =Q13/Q5 -> 0.12945677 | Q13: =$B13/12 -> 224497.46 | R13: =S13/S5 -> 0.12945677 | S13: =$B13/12 -> 224497.46 | T13: =U13/U5 -> 0.12945677 | U13: =$B13/12 -> 224497.46 | V13: =W13/W5 -> 0.12945677 | W13: =$B13/12 -> 224497.46 | X13: =Y13/Y5 -> 0.12945677 | Y13: =$B13/12 -> 224497.46 | Z13: =AA13/AA5 -> 0.12945677 | AA13: =$B13/12 -> 224497.46 | AB13: =AC13/AC5 -> 0.12945677 | AC13: =E13+G13+I13+K13+M13+O13+Q13+S13+U13+W13+Y13+AA13 -> 2693969.5 | AD13: =Activos!L135 -> 3098065 | AE13: =AF13/AF5 -> 0.14044838 | AF13: =$AD13/12 -> 258172.08 | AG13: =AH13/AH5 -> 0.14044838 | AH13: =$AD13/12 -> 258172.08 | AI13: =AJ13/AJ5 -> 0.14044838 | AJ13: =$AD13/12 -> 258172.08 | AK13: =AL13/AL5 -> 0.14044838 | AL13: =$AD13/12 -> 258172.08 | AM13: =AN13/AN5 -> 0.14044838 | AN13: =$AD13/12 -> 258172.08 | AO13: =AP13/AP5 -> 0.14044838 | AP13: =$AD13/12 -> 258172.08 | AQ13: =AR13/AR5 -> 0.14044838 | AR13: =$AD13/12 -> 258172.08 | AS13: =AT13/AT5 -> 0.14044838 | AT13: =$AD13/12 -> 258172.08 | AU13: =AV13/AV5 -> 0.14044838 | AV13: =$AD13/12 -> 258172.08 | AW13: =AX13/AX5 -> 0.14044838 | AX13: =$AD13/12 -> 258172.08 | AY13: =AZ13/AZ5 -> 0.14044838 | AZ13: =$AD13/12 -> 258172.08 | BA13: =BB13/BB5 -> 0.14044838 | BB13: =$AD13/12 -> 258172.08 | BC13: =BD13/BD5 -> 0.14044838 | BD13: =AF13+AH13+AJ13+AL13+AN13+AP13+AR13+AT13+AV13+AX13+AZ13+BB13 -> 3098065
B14: =Activos!K116 -> 4829800.9 | C14: Belén | D14: =E14/E6 -> 0.12799193 | E14: =$B14/12 -> 402483.41 | F14: =G14/G6 -> 0.12799193 | G14: =$B14/12 -> 402483.41 | H14: =I14/I6 -> 0.12799193 | I14: =$B14/12 -> 402483.41 | J14: =K14/K6 -> 0.12799193 | K14: =$B14/12 -> 402483.41 | L14: =M14/M6 -> 0.12799193 | M14: =$B14/12 -> 402483.41 | N14: =O14/O6 -> 0.12799193 | O14: =$B14/12 -> 402483.41 | P14: =Q14/Q6 -> 0.12178109 | Q14: =$B14/12 -> 402483.41 | R14: =S14/S6 -> 0.12178109 | S14: =$B14/12 -> 402483.41 | T14: =U14/U6 -> 0.12178109 | U14: =$B14/12 -> 402483.41 | V14: =W14/W6 -> 0.12178109 | W14: =$B14/12 -> 402483.41 | X14: =Y14/Y6 -> 0.12178109 | Y14: =$B14/12 -> 402483.41 | Z14: =AA14/AA6 -> 0.12178109 | AA14: =$B14/12 -> 402483.41 | AB14: =AC14/AC6 -> 0.12480929 | AC14: =E14+G14+I14+K14+M14+O14+Q14+S14+U14+W14+Y14+AA14 -> 4829800.9 | AD14: =Activos!L116 -> 5554271.1 | AE14: =AF14/AF6 -> 0.14004825 | AF14: =$AD14/12 -> 462855.92 | AG14: =AH14/AH6 -> 0.14004825 | AH14: =$AD14/12 -> 462855.92 | AI14: =AJ14/AJ6 -> 0.14004825 | AJ14: =$AD14/12 -> 462855.92 | AK14: =AL14/AL6 -> 0.14004825 | AL14: =$AD14/12 -> 462855.92 | AM14: =AN14/AN6 -> 0.14004825 | AN14: =$AD14/12 -> 462855.92 | AO14: =AP14/AP6 -> 0.14004825 | AP14: =$AD14/12 -> 462855.92 | AQ14: =AR14/AR6 -> 0.13212099 | AR14: =$AD14/12 -> 462855.92 | AS14: =AT14/AT6 -> 0.13212099 | AT14: =$AD14/12 -> 462855.92 | AU14: =AV14/AV6 -> 0.13212099 | AV14: =$AD14/12 -> 462855.92 | AW14: =AX14/AX6 -> 0.13212099 | AX14: =$AD14/12 -> 462855.92 | AY14: =AZ14/AZ6 -> 0.13212099 | AZ14: =$AD14/12 -> 462855.92 | BA14: =BB14/BB6 -> 0.13212099 | BB14: =$AD14/12 -> 462855.92 | BC14: =BD14/BD6 -> 0.13596918 | BD14: =AF14+AH14+AJ14+AL14+AN14+AP14+AR14+AT14+AV14+AX14+AZ14+BB14 -> 5554271.1
B15: =Activos!K40 -> 1995686.7 | C15: Ocarinas | D15: =E15/E7 -> 0.10941265 | E15: =$B15/12 -> 166307.23 | F15: =G15/G7 -> 0.10941265 | G15: =$B15/12 -> 166307.23 | H15: =I15/I7 -> 0.10941265 | I15: =$B15/12 -> 166307.23 | J15: =K15/K7 -> 0.10941265 | K15: =$B15/12 -> 166307.23 | L15: =M15/M7 -> 0.10941265 | M15: =$B15/12 -> 166307.23 | N15: =O15/O7 -> 0.085285758 | O15: =$B15/12 -> 166307.23 | P15: =Q15/Q7 -> 0.079193918 | Q15: =$B15/12 -> 166307.23 | R15: =S15/S7 -> 0.079193918 | S15: =$B15/12 -> 166307.23 | T15: =U15/U7 -> 0.079193918 | U15: =$B15/12 -> 166307.23 | V15: =W15/W7 -> 0.079193918 | W15: =$B15/12 -> 166307.23 | X15: =Y15/Y7 -> 0.079193918 | Y15: =$B15/12 -> 166307.23 | Z15: =AA15/AA7 -> 0.079193918 | AA15: =$B15/12 -> 166307.23 | AB15: =AC15/AC7 -> 0.090098724 | AC15: =E15+G15+I15+K15+M15+O15+Q15+S15+U15+W15+Y15+AA15 -> 1995686.7 | AD15: =Activos!L40 -> 2295039.7 | AE15: =AF15/AF7 -> 0.11971888 | AF15: =$AD15/12 -> 191253.31 | AG15: =AH15/AH7 -> 0.11971888 | AH15: =$AD15/12 -> 191253.31 | AI15: =AJ15/AJ7 -> 0.11971888 | AJ15: =$AD15/12 -> 191253.31 | AK15: =AL15/AL7 -> 0.11971888 | AL15: =$AD15/12 -> 191253.31 | AM15: =AN15/AN7 -> 0.11971888 | AN15: =$AD15/12 -> 191253.31 | AO15: =AP15/AP7 -> 0.11294234 | AP15: =$AD15/12 -> 191253.31 | AQ15: =AR15/AR7 -> 0.11294234 | AR15: =$AD15/12 -> 191253.31 | AS15: =AT15/AT7 -> 0.11294234 | AT15: =$AD15/12 -> 191253.31 | AU15: =AV15/AV7 -> 0.11294234 | AV15: =$AD15/12 -> 191253.31 | AW15: =AX15/AX7 -> 0.11294234 | AX15: =$AD15/12 -> 191253.31 | AY15: =AZ15/AZ7 -> 0.11294234 | AZ15: =$AD15/12 -> 191253.31 | BA15: =BB15/BB7 -> 0.11294234 | BB15: =$AD15/12 -> 191253.31 | BC15: =BD15/BD7 -> 0.11567042 | BD15: =AF15+AH15+AJ15+AL15+AN15+AP15+AR15+AT15+AV15+AX15+AZ15+BB15 -> 2295039.7
B16: =Activos!K97 -> 391504.32 | C16: Pedregal | D16: =E16/E8 -> 0.065250719 | E16: =$B16/12 -> 32625.36 | F16: =G16/G8 -> 0.065250719 | G16: =$B16/12 -> 32625.36 | H16: =I16/I8 -> 0.065250719 | I16: =$B16/12 -> 32625.36 | J16: =K16/K8 -> 0.065250719 | K16: =$B16/12 -> 32625.36 | L16: =M16/M8 -> 0.065250719 | M16: =$B16/12 -> 32625.36 | N16: =O16/O8 -> 0.062084414 | O16: =$B16/12 -> 32625.36 | P16: =Q16/Q8 -> 0.062084414 | Q16: =$B16/12 -> 32625.36 | R16: =S16/S8 -> 0.062084414 | S16: =$B16/12 -> 32625.36 | T16: =U16/U8 -> 0.062084414 | U16: =$B16/12 -> 32625.36 | V16: =W16/W8 -> 0.062084414 | W16: =$B16/12 -> 32625.36 | X16: =Y16/Y8 -> 0.062084414 | Y16: =$B16/12 -> 32625.36 | Z16: =AA16/AA8 -> 0.062084414 | AA16: =$B16/12 -> 32625.36 | AB16: =AC16/AC8 -> 0.063365593 | AC16: =E16+G16+I16+K16+M16+O16+Q16+S16+U16+W16+Y16+AA16 -> 391504.32 | AD16: =Activos!L97 -> 450229.96 | AE16: =AF16/AF8 -> 0.071397076 | AF16: =$AD16/12 -> 37519.164 | AG16: =AH16/AH8 -> 0.071397076 | AH16: =$AD16/12 -> 37519.164 | AI16: =AJ16/AJ8 -> 0.071397076 | AJ16: =$AD16/12 -> 37519.164 | AK16: =AL16/AL8 -> 0.071397076 | AL16: =$AD16/12 -> 37519.164 | AM16: =AN16/AN8 -> 0.071397076 | AN16: =$AD16/12 -> 37519.164 | AO16: =AP16/AP8 -> 0.071397076 | AP16: =$AD16/12 -> 37519.164 | AQ16: =AR16/AR8 -> 0.071397076 | AR16: =$AD16/12 -> 37519.164 | AS16: =AT16/AT8 -> 0.071397076 | AT16: =$AD16/12 -> 37519.164 | AU16: =AV16/AV8 -> 0.071397076 | AV16: =$AD16/12 -> 37519.164 | AW16: =AX16/AX8 -> 0.071397076 | AX16: =$AD16/12 -> 37519.164 | AY16: =AZ16/AZ8 -> 0.071397076 | AZ16: =$AD16/12 -> 37519.164 | BA16: =BB16/BB8 -> 0.067355732 | BB16: =$AD16/12 -> 37519.164 | BC16: =BD16/BD8 -> 0.071041867 | BD16: =AF16+AH16+AJ16+AL16+AN16+AP16+AR16+AT16+AV16+AX16+AZ16+BB16 -> 450229.96
B17: =Activos!K59 -> 1448475 | C17: Rivera del Valle | D17: =E17/E9 -> 0.070382655 | E17: =$B17/12 -> 120706.25 | F17: =G17/G9 -> 0.070382655 | G17: =$B17/12 -> 120706.25 | H17: =I17/I9 -> 0.070382655 | I17: =$B17/12 -> 120706.25 | J17: =K17/K9 -> 0.070382655 | K17: =$B17/12 -> 120706.25 | L17: =M17/M9 -> 0.070382655 | M17: =$B17/12 -> 120706.25 | N17: =O17/O9 -> 0.070382655 | O17: =$B17/12 -> 120706.25 | P17: =Q17/Q9 -> 0.070382655 | Q17: =$B17/12 -> 120706.25 | R17: =S17/S9 -> 0.070382655 | S17: =$B17/12 -> 120706.25 | T17: =U17/U9 -> 0.070382655 | U17: =$B17/12 -> 120706.25 | V17: =W17/W9 -> 0.070382655 | W17: =$B17/12 -> 120706.25 | X17: =Y17/Y9 -> 0.070382655 | Y17: =$B17/12 -> 120706.25 | Z17: =AA17/AA9 -> 0.066967322 | AA17: =$B17/12 -> 120706.25 | AB17: =AC17/AC9 -> 0.070084795 | AC17: =E17+G17+I17+K17+M17+O17+Q17+S17+U17+W17+Y17+AA17 -> 1448475 | AD17: =Activos!L59 -> 1665746.3 | AE17: =AF17/AF9 -> 0.07701242 | AF17: =$AD17/12 -> 138812.19 | AG17: =AH17/AH9 -> 0.07701242 | AH17: =$AD17/12 -> 138812.19 | AI17: =AJ17/AJ9 -> 0.07701242 | AJ17: =$AD17/12 -> 138812.19 | AK17: =AL17/AL9 -> 0.07701242 | AL17: =$AD17/12 -> 138812.19 | AM17: =AN17/AN9 -> 0.07701242 | AN17: =$AD17/12 -> 138812.19 | AO17: =AP17/AP9 -> 0.07701242 | AP17: =$AD17/12 -> 138812.19 | AQ17: =AR17/AR9 -> 0.07701242 | AR17: =$AD17/12 -> 138812.19 | AS17: =AT17/AT9 -> 0.07701242 | AT17: =$AD17/12 -> 138812.19 | AU17: =AV17/AV9 -> 0.07701242 | AV17: =$AD17/12 -> 138812.19 | AW17: =AX17/AX9 -> 0.07701242 | AX17: =$AD17/12 -> 138812.19 | AY17: =AZ17/AZ9 -> 0.07701242 | AZ17: =$AD17/12 -> 138812.19 | BA17: =BB17/BB9 -> 0.072653227 | BB17: =$AD17/12 -> 138812.19 | BC17: =BD17/BD9 -> 0.076629274 | BD17: =AF17+AH17+AJ17+AL17+AN17+AP17+AR17+AT17+AV17+AX17+AZ17+BB17 -> 1665746.3
